{"TestFile": "test_boptestGymEnv.py", "NCases": 19, "NPassed": 1, "NErrors": 16, "NFailures": 2, "Failures": {"0": "Traceback (most recent call last):\n  File \"/home/marius/Desktop/project1-boptest-gym/testing/test_boptestGymEnv.py\", line 98, in test_reset_fixed\n    self.compare_ref_values_df(df, ref_filepath)\n  File \"/home/marius/Desktop/project1-boptest-gym/testing/utilities.py\", line 245, in compare_ref_values_df\n    self.assertTrue(results['Pass'], '{0} Key is {1}.'.format(results['Message'],key))\nAssertionError: False is not true : Max error (0.9982870907557634) in trajectory greater than tolerance (0.001) at index 0. y_test: 295.0382995605469, y_ref:294.0433959960937 Key is obs_reset_fixed.\n", "1": "Traceback (most recent call last):\n  File \"/home/marius/Desktop/project1-boptest-gym/testing/test_boptestGymEnv.py\", line 135, in test_reset_random\n    self.compare_ref_values_df(df, ref_filepath)\n  File \"/home/marius/Desktop/project1-boptest-gym/testing/utilities.py\", line 245, in compare_ref_values_df\n    self.assertTrue(results['Pass'], '{0} Key is {1}.'.format(results['Message'],key))\nAssertionError: False is not true : Max error (1.8308782083863118) in trajectory greater than tolerance (0.001) at index 0. y_test: 294.60125732421875, y_ref:292.776611328125 Key is 28313766.\n"}, "Errors": {"0": "Traceback (most recent call last):\n  File \"/home/marius/miniconda3/envs/ccai2022/lib/python3.10/site-packages/urllib3/connection.py\", line 174, in _new_conn\n    conn = connection.create_connection(\n  File \"/home/marius/miniconda3/envs/ccai2022/lib/python3.10/site-packages/urllib3/util/connection.py\", line 95, in create_connection\n    raise err\n  File \"/home/marius/miniconda3/envs/ccai2022/lib/python3.10/site-packages/urllib3/util/connection.py\", line 85, in create_connection\n    sock.connect(sa)\nConnectionRefusedError: [Errno 111] Connection refused\n\nDuring handling of the above exception, another exception occurred:\n\nTraceback (most recent call last):\n  File \"/home/marius/miniconda3/envs/ccai2022/lib/python3.10/site-packages/urllib3/connectionpool.py\", line 703, in urlopen\n    httplib_response = self._make_request(\n  File \"/home/marius/miniconda3/envs/ccai2022/lib/python3.10/site-packages/urllib3/connectionpool.py\", line 398, in _make_request\n    conn.request(method, url, **httplib_request_kw)\n  File \"/home/marius/miniconda3/envs/ccai2022/lib/python3.10/site-packages/urllib3/connection.py\", line 239, in request\n    super(HTTPConnection, self).request(method, url, body=body, headers=headers)\n  File \"/home/marius/miniconda3/envs/ccai2022/lib/python3.10/http/client.py\", line 1282, in request\n    self._send_request(method, url, body, headers, encode_chunked)\n  File \"/home/marius/miniconda3/envs/ccai2022/lib/python3.10/http/client.py\", line 1328, in _send_request\n    self.endheaders(body, encode_chunked=encode_chunked)\n  File \"/home/marius/miniconda3/envs/ccai2022/lib/python3.10/http/client.py\", line 1277, in endheaders\n    self._send_output(message_body, encode_chunked=encode_chunked)\n  File \"/home/marius/miniconda3/envs/ccai2022/lib/python3.10/http/client.py\", line 1037, in _send_output\n    self.send(msg)\n  File \"/home/marius/miniconda3/envs/ccai2022/lib/python3.10/http/client.py\", line 975, in send\n    self.connect()\n  File \"/home/marius/miniconda3/envs/ccai2022/lib/python3.10/site-packages/urllib3/connection.py\", line 205, in connect\n    conn = self._new_conn()\n  File \"/home/marius/miniconda3/envs/ccai2022/lib/python3.10/site-packages/urllib3/connection.py\", line 186, in _new_conn\n    raise NewConnectionError(\nurllib3.exceptions.NewConnectionError: <urllib3.connection.HTTPConnection object at 0x7f0b18b981c0>: Failed to establish a new connection: [Errno 111] Connection refused\n\nDuring handling of the above exception, another exception occurred:\n\nTraceback (most recent call last):\n  File \"/home/marius/miniconda3/envs/ccai2022/lib/python3.10/site-packages/requests/adapters.py\", line 440, in send\n    resp = conn.urlopen(\n  File \"/home/marius/miniconda3/envs/ccai2022/lib/python3.10/site-packages/urllib3/connectionpool.py\", line 785, in urlopen\n    retries = retries.increment(\n  File \"/home/marius/miniconda3/envs/ccai2022/lib/python3.10/site-packages/urllib3/util/retry.py\", line 592, in increment\n    raise MaxRetryError(_pool, url, error or ResponseError(cause))\nurllib3.exceptions.MaxRetryError: HTTPConnectionPool(host='127.0.0.1', port=5000): Max retries exceeded with url: /name (Caused by NewConnectionError('<urllib3.connection.HTTPConnection object at 0x7f0b18b981c0>: Failed to establish a new connection: [Errno 111] Connection refused'))\n\nDuring handling of the above exception, another exception occurred:\n\nTraceback (most recent call last):\n  File \"/home/marius/Desktop/project1-boptest-gym/testing/test_boptestGymEnv.py\", line 253, in test_A2C_A\n    self.partial_test_RL(case='A', algorithm='A2C')\n  File \"/home/marius/Desktop/project1-boptest-gym/testing/test_boptestGymEnv.py\", line 212, in partial_test_RL\n    env, model, start_time_tests, _ = train_RL.train_RL(algorithm=algorithm,\n  File \"/home/marius/Desktop/project1-boptest-gym/examples/train_RL.py\", line 120, in train_RL\n    env = BoptestGymEnvCustomReward(\n  File \"/home/marius/Desktop/project1-boptest-gym/boptestGymEnv.py\", line 164, in __init__\n    self.name = requests.get('{0}/name'.format(url)).json()['payload']\n  File \"/home/marius/miniconda3/envs/ccai2022/lib/python3.10/site-packages/requests/api.py\", line 75, in get\n    return request('get', url, params=params, **kwargs)\n  File \"/home/marius/miniconda3/envs/ccai2022/lib/python3.10/site-packages/requests/api.py\", line 61, in request\n    return session.request(method=method, url=url, **kwargs)\n  File \"/home/marius/miniconda3/envs/ccai2022/lib/python3.10/site-packages/requests/sessions.py\", line 529, in request\n    resp = self.send(prep, **send_kwargs)\n  File \"/home/marius/miniconda3/envs/ccai2022/lib/python3.10/site-packages/requests/sessions.py\", line 645, in send\n    r = adapter.send(request, **kwargs)\n  File \"/home/marius/miniconda3/envs/ccai2022/lib/python3.10/site-packages/requests/adapters.py\", line 519, in send\n    raise ConnectionError(e, request=request)\nrequests.exceptions.ConnectionError: HTTPConnectionPool(host='127.0.0.1', port=5000): Max retries exceeded with url: /name (Caused by NewConnectionError('<urllib3.connection.HTTPConnection object at 0x7f0b18b981c0>: Failed to establish a new connection: [Errno 111] Connection refused'))\n", "1": "Traceback (most recent call last):\n  File \"/home/marius/miniconda3/envs/ccai2022/lib/python3.10/site-packages/urllib3/connection.py\", line 174, in _new_conn\n    conn = connection.create_connection(\n  File \"/home/marius/miniconda3/envs/ccai2022/lib/python3.10/site-packages/urllib3/util/connection.py\", line 95, in create_connection\n    raise err\n  File \"/home/marius/miniconda3/envs/ccai2022/lib/python3.10/site-packages/urllib3/util/connection.py\", line 85, in create_connection\n    sock.connect(sa)\nConnectionRefusedError: [Errno 111] Connection refused\n\nDuring handling of the above exception, another exception occurred:\n\nTraceback (most recent call last):\n  File \"/home/marius/miniconda3/envs/ccai2022/lib/python3.10/site-packages/urllib3/connectionpool.py\", line 703, in urlopen\n    httplib_response = self._make_request(\n  File \"/home/marius/miniconda3/envs/ccai2022/lib/python3.10/site-packages/urllib3/connectionpool.py\", line 398, in _make_request\n    conn.request(method, url, **httplib_request_kw)\n  File \"/home/marius/miniconda3/envs/ccai2022/lib/python3.10/site-packages/urllib3/connection.py\", line 239, in request\n    super(HTTPConnection, self).request(method, url, body=body, headers=headers)\n  File \"/home/marius/miniconda3/envs/ccai2022/lib/python3.10/http/client.py\", line 1282, in request\n    self._send_request(method, url, body, headers, encode_chunked)\n  File \"/home/marius/miniconda3/envs/ccai2022/lib/python3.10/http/client.py\", line 1328, in _send_request\n    self.endheaders(body, encode_chunked=encode_chunked)\n  File \"/home/marius/miniconda3/envs/ccai2022/lib/python3.10/http/client.py\", line 1277, in endheaders\n    self._send_output(message_body, encode_chunked=encode_chunked)\n  File \"/home/marius/miniconda3/envs/ccai2022/lib/python3.10/http/client.py\", line 1037, in _send_output\n    self.send(msg)\n  File \"/home/marius/miniconda3/envs/ccai2022/lib/python3.10/http/client.py\", line 975, in send\n    self.connect()\n  File \"/home/marius/miniconda3/envs/ccai2022/lib/python3.10/site-packages/urllib3/connection.py\", line 205, in connect\n    conn = self._new_conn()\n  File \"/home/marius/miniconda3/envs/ccai2022/lib/python3.10/site-packages/urllib3/connection.py\", line 186, in _new_conn\n    raise NewConnectionError(\nurllib3.exceptions.NewConnectionError: <urllib3.connection.HTTPConnection object at 0x7f0b18b99480>: Failed to establish a new connection: [Errno 111] Connection refused\n\nDuring handling of the above exception, another exception occurred:\n\nTraceback (most recent call last):\n  File \"/home/marius/miniconda3/envs/ccai2022/lib/python3.10/site-packages/requests/adapters.py\", line 440, in send\n    resp = conn.urlopen(\n  File \"/home/marius/miniconda3/envs/ccai2022/lib/python3.10/site-packages/urllib3/connectionpool.py\", line 785, in urlopen\n    retries = retries.increment(\n  File \"/home/marius/miniconda3/envs/ccai2022/lib/python3.10/site-packages/urllib3/util/retry.py\", line 592, in increment\n    raise MaxRetryError(_pool, url, error or ResponseError(cause))\nurllib3.exceptions.MaxRetryError: HTTPConnectionPool(host='127.0.0.1', port=5000): Max retries exceeded with url: /name (Caused by NewConnectionError('<urllib3.connection.HTTPConnection object at 0x7f0b18b99480>: Failed to establish a new connection: [Errno 111] Connection refused'))\n\nDuring handling of the above exception, another exception occurred:\n\nTraceback (most recent call last):\n  File \"/home/marius/Desktop/project1-boptest-gym/testing/test_boptestGymEnv.py\", line 262, in test_A2C_B\n    self.partial_test_RL(case='B', algorithm='A2C')\n  File \"/home/marius/Desktop/project1-boptest-gym/testing/test_boptestGymEnv.py\", line 212, in partial_test_RL\n    env, model, start_time_tests, _ = train_RL.train_RL(algorithm=algorithm,\n  File \"/home/marius/Desktop/project1-boptest-gym/examples/train_RL.py\", line 136, in train_RL\n    env = BoptestGymEnvCustomReward(\n  File \"/home/marius/Desktop/project1-boptest-gym/boptestGymEnv.py\", line 164, in __init__\n    self.name = requests.get('{0}/name'.format(url)).json()['payload']\n  File \"/home/marius/miniconda3/envs/ccai2022/lib/python3.10/site-packages/requests/api.py\", line 75, in get\n    return request('get', url, params=params, **kwargs)\n  File \"/home/marius/miniconda3/envs/ccai2022/lib/python3.10/site-packages/requests/api.py\", line 61, in request\n    return session.request(method=method, url=url, **kwargs)\n  File \"/home/marius/miniconda3/envs/ccai2022/lib/python3.10/site-packages/requests/sessions.py\", line 529, in request\n    resp = self.send(prep, **send_kwargs)\n  File \"/home/marius/miniconda3/envs/ccai2022/lib/python3.10/site-packages/requests/sessions.py\", line 645, in send\n    r = adapter.send(request, **kwargs)\n  File \"/home/marius/miniconda3/envs/ccai2022/lib/python3.10/site-packages/requests/adapters.py\", line 519, in send\n    raise ConnectionError(e, request=request)\nrequests.exceptions.ConnectionError: HTTPConnectionPool(host='127.0.0.1', port=5000): Max retries exceeded with url: /name (Caused by NewConnectionError('<urllib3.connection.HTTPConnection object at 0x7f0b18b99480>: Failed to establish a new connection: [Errno 111] Connection refused'))\n", "2": "Traceback (most recent call last):\n  File \"/home/marius/miniconda3/envs/ccai2022/lib/python3.10/site-packages/urllib3/connection.py\", line 174, in _new_conn\n    conn = connection.create_connection(\n  File \"/home/marius/miniconda3/envs/ccai2022/lib/python3.10/site-packages/urllib3/util/connection.py\", line 95, in create_connection\n    raise err\n  File \"/home/marius/miniconda3/envs/ccai2022/lib/python3.10/site-packages/urllib3/util/connection.py\", line 85, in create_connection\n    sock.connect(sa)\nConnectionRefusedError: [Errno 111] Connection refused\n\nDuring handling of the above exception, another exception occurred:\n\nTraceback (most recent call last):\n  File \"/home/marius/miniconda3/envs/ccai2022/lib/python3.10/site-packages/urllib3/connectionpool.py\", line 703, in urlopen\n    httplib_response = self._make_request(\n  File \"/home/marius/miniconda3/envs/ccai2022/lib/python3.10/site-packages/urllib3/connectionpool.py\", line 398, in _make_request\n    conn.request(method, url, **httplib_request_kw)\n  File \"/home/marius/miniconda3/envs/ccai2022/lib/python3.10/site-packages/urllib3/connection.py\", line 239, in request\n    super(HTTPConnection, self).request(method, url, body=body, headers=headers)\n  File \"/home/marius/miniconda3/envs/ccai2022/lib/python3.10/http/client.py\", line 1282, in request\n    self._send_request(method, url, body, headers, encode_chunked)\n  File \"/home/marius/miniconda3/envs/ccai2022/lib/python3.10/http/client.py\", line 1328, in _send_request\n    self.endheaders(body, encode_chunked=encode_chunked)\n  File \"/home/marius/miniconda3/envs/ccai2022/lib/python3.10/http/client.py\", line 1277, in endheaders\n    self._send_output(message_body, encode_chunked=encode_chunked)\n  File \"/home/marius/miniconda3/envs/ccai2022/lib/python3.10/http/client.py\", line 1037, in _send_output\n    self.send(msg)\n  File \"/home/marius/miniconda3/envs/ccai2022/lib/python3.10/http/client.py\", line 975, in send\n    self.connect()\n  File \"/home/marius/miniconda3/envs/ccai2022/lib/python3.10/site-packages/urllib3/connection.py\", line 205, in connect\n    conn = self._new_conn()\n  File \"/home/marius/miniconda3/envs/ccai2022/lib/python3.10/site-packages/urllib3/connection.py\", line 186, in _new_conn\n    raise NewConnectionError(\nurllib3.exceptions.NewConnectionError: <urllib3.connection.HTTPConnection object at 0x7f0b18b99d80>: Failed to establish a new connection: [Errno 111] Connection refused\n\nDuring handling of the above exception, another exception occurred:\n\nTraceback (most recent call last):\n  File \"/home/marius/miniconda3/envs/ccai2022/lib/python3.10/site-packages/requests/adapters.py\", line 440, in send\n    resp = conn.urlopen(\n  File \"/home/marius/miniconda3/envs/ccai2022/lib/python3.10/site-packages/urllib3/connectionpool.py\", line 785, in urlopen\n    retries = retries.increment(\n  File \"/home/marius/miniconda3/envs/ccai2022/lib/python3.10/site-packages/urllib3/util/retry.py\", line 592, in increment\n    raise MaxRetryError(_pool, url, error or ResponseError(cause))\nurllib3.exceptions.MaxRetryError: HTTPConnectionPool(host='127.0.0.1', port=5000): Max retries exceeded with url: /name (Caused by NewConnectionError('<urllib3.connection.HTTPConnection object at 0x7f0b18b99d80>: Failed to establish a new connection: [Errno 111] Connection refused'))\n\nDuring handling of the above exception, another exception occurred:\n\nTraceback (most recent call last):\n  File \"/home/marius/Desktop/project1-boptest-gym/testing/test_boptestGymEnv.py\", line 270, in test_A2C_C\n    self.partial_test_RL(case='C', algorithm='A2C')\n  File \"/home/marius/Desktop/project1-boptest-gym/testing/test_boptestGymEnv.py\", line 212, in partial_test_RL\n    env, model, start_time_tests, _ = train_RL.train_RL(algorithm=algorithm,\n  File \"/home/marius/Desktop/project1-boptest-gym/examples/train_RL.py\", line 154, in train_RL\n    env = BoptestGymEnvCustomReward(\n  File \"/home/marius/Desktop/project1-boptest-gym/boptestGymEnv.py\", line 164, in __init__\n    self.name = requests.get('{0}/name'.format(url)).json()['payload']\n  File \"/home/marius/miniconda3/envs/ccai2022/lib/python3.10/site-packages/requests/api.py\", line 75, in get\n    return request('get', url, params=params, **kwargs)\n  File \"/home/marius/miniconda3/envs/ccai2022/lib/python3.10/site-packages/requests/api.py\", line 61, in request\n    return session.request(method=method, url=url, **kwargs)\n  File \"/home/marius/miniconda3/envs/ccai2022/lib/python3.10/site-packages/requests/sessions.py\", line 529, in request\n    resp = self.send(prep, **send_kwargs)\n  File \"/home/marius/miniconda3/envs/ccai2022/lib/python3.10/site-packages/requests/sessions.py\", line 645, in send\n    r = adapter.send(request, **kwargs)\n  File \"/home/marius/miniconda3/envs/ccai2022/lib/python3.10/site-packages/requests/adapters.py\", line 519, in send\n    raise ConnectionError(e, request=request)\nrequests.exceptions.ConnectionError: HTTPConnectionPool(host='127.0.0.1', port=5000): Max retries exceeded with url: /name (Caused by NewConnectionError('<urllib3.connection.HTTPConnection object at 0x7f0b18b99d80>: Failed to establish a new connection: [Errno 111] Connection refused'))\n", "3": "Traceback (most recent call last):\n  File \"/home/marius/miniconda3/envs/ccai2022/lib/python3.10/site-packages/urllib3/connection.py\", line 174, in _new_conn\n    conn = connection.create_connection(\n  File \"/home/marius/miniconda3/envs/ccai2022/lib/python3.10/site-packages/urllib3/util/connection.py\", line 95, in create_connection\n    raise err\n  File \"/home/marius/miniconda3/envs/ccai2022/lib/python3.10/site-packages/urllib3/util/connection.py\", line 85, in create_connection\n    sock.connect(sa)\nConnectionRefusedError: [Errno 111] Connection refused\n\nDuring handling of the above exception, another exception occurred:\n\nTraceback (most recent call last):\n  File \"/home/marius/miniconda3/envs/ccai2022/lib/python3.10/site-packages/urllib3/connectionpool.py\", line 703, in urlopen\n    httplib_response = self._make_request(\n  File \"/home/marius/miniconda3/envs/ccai2022/lib/python3.10/site-packages/urllib3/connectionpool.py\", line 398, in _make_request\n    conn.request(method, url, **httplib_request_kw)\n  File \"/home/marius/miniconda3/envs/ccai2022/lib/python3.10/site-packages/urllib3/connection.py\", line 239, in request\n    super(HTTPConnection, self).request(method, url, body=body, headers=headers)\n  File \"/home/marius/miniconda3/envs/ccai2022/lib/python3.10/http/client.py\", line 1282, in request\n    self._send_request(method, url, body, headers, encode_chunked)\n  File \"/home/marius/miniconda3/envs/ccai2022/lib/python3.10/http/client.py\", line 1328, in _send_request\n    self.endheaders(body, encode_chunked=encode_chunked)\n  File \"/home/marius/miniconda3/envs/ccai2022/lib/python3.10/http/client.py\", line 1277, in endheaders\n    self._send_output(message_body, encode_chunked=encode_chunked)\n  File \"/home/marius/miniconda3/envs/ccai2022/lib/python3.10/http/client.py\", line 1037, in _send_output\n    self.send(msg)\n  File \"/home/marius/miniconda3/envs/ccai2022/lib/python3.10/http/client.py\", line 975, in send\n    self.connect()\n  File \"/home/marius/miniconda3/envs/ccai2022/lib/python3.10/site-packages/urllib3/connection.py\", line 205, in connect\n    conn = self._new_conn()\n  File \"/home/marius/miniconda3/envs/ccai2022/lib/python3.10/site-packages/urllib3/connection.py\", line 186, in _new_conn\n    raise NewConnectionError(\nurllib3.exceptions.NewConnectionError: <urllib3.connection.HTTPConnection object at 0x7f0b18b9a950>: Failed to establish a new connection: [Errno 111] Connection refused\n\nDuring handling of the above exception, another exception occurred:\n\nTraceback (most recent call last):\n  File \"/home/marius/miniconda3/envs/ccai2022/lib/python3.10/site-packages/requests/adapters.py\", line 440, in send\n    resp = conn.urlopen(\n  File \"/home/marius/miniconda3/envs/ccai2022/lib/python3.10/site-packages/urllib3/connectionpool.py\", line 785, in urlopen\n    retries = retries.increment(\n  File \"/home/marius/miniconda3/envs/ccai2022/lib/python3.10/site-packages/urllib3/util/retry.py\", line 592, in increment\n    raise MaxRetryError(_pool, url, error or ResponseError(cause))\nurllib3.exceptions.MaxRetryError: HTTPConnectionPool(host='127.0.0.1', port=5000): Max retries exceeded with url: /name (Caused by NewConnectionError('<urllib3.connection.HTTPConnection object at 0x7f0b18b9a950>: Failed to establish a new connection: [Errno 111] Connection refused'))\n\nDuring handling of the above exception, another exception occurred:\n\nTraceback (most recent call last):\n  File \"/home/marius/Desktop/project1-boptest-gym/testing/test_boptestGymEnv.py\", line 244, in test_A2C_simple\n    self.partial_test_RL(case='simple', algorithm='A2C', episode_length_test=2*24*3600)\n  File \"/home/marius/Desktop/project1-boptest-gym/testing/test_boptestGymEnv.py\", line 212, in partial_test_RL\n    env, model, start_time_tests, _ = train_RL.train_RL(algorithm=algorithm,\n  File \"/home/marius/Desktop/project1-boptest-gym/examples/train_RL.py\", line 108, in train_RL\n    env = BoptestGymEnvCustomReward(\n  File \"/home/marius/Desktop/project1-boptest-gym/boptestGymEnv.py\", line 164, in __init__\n    self.name = requests.get('{0}/name'.format(url)).json()['payload']\n  File \"/home/marius/miniconda3/envs/ccai2022/lib/python3.10/site-packages/requests/api.py\", line 75, in get\n    return request('get', url, params=params, **kwargs)\n  File \"/home/marius/miniconda3/envs/ccai2022/lib/python3.10/site-packages/requests/api.py\", line 61, in request\n    return session.request(method=method, url=url, **kwargs)\n  File \"/home/marius/miniconda3/envs/ccai2022/lib/python3.10/site-packages/requests/sessions.py\", line 529, in request\n    resp = self.send(prep, **send_kwargs)\n  File \"/home/marius/miniconda3/envs/ccai2022/lib/python3.10/site-packages/requests/sessions.py\", line 645, in send\n    r = adapter.send(request, **kwargs)\n  File \"/home/marius/miniconda3/envs/ccai2022/lib/python3.10/site-packages/requests/adapters.py\", line 519, in send\n    raise ConnectionError(e, request=request)\nrequests.exceptions.ConnectionError: HTTPConnectionPool(host='127.0.0.1', port=5000): Max retries exceeded with url: /name (Caused by NewConnectionError('<urllib3.connection.HTTPConnection object at 0x7f0b18b9a950>: Failed to establish a new connection: [Errno 111] Connection refused'))\n", "4": "Traceback (most recent call last):\n  File \"/home/marius/miniconda3/envs/ccai2022/lib/python3.10/site-packages/urllib3/connection.py\", line 174, in _new_conn\n    conn = connection.create_connection(\n  File \"/home/marius/miniconda3/envs/ccai2022/lib/python3.10/site-packages/urllib3/util/connection.py\", line 95, in create_connection\n    raise err\n  File \"/home/marius/miniconda3/envs/ccai2022/lib/python3.10/site-packages/urllib3/util/connection.py\", line 85, in create_connection\n    sock.connect(sa)\nConnectionRefusedError: [Errno 111] Connection refused\n\nDuring handling of the above exception, another exception occurred:\n\nTraceback (most recent call last):\n  File \"/home/marius/miniconda3/envs/ccai2022/lib/python3.10/site-packages/urllib3/connectionpool.py\", line 703, in urlopen\n    httplib_response = self._make_request(\n  File \"/home/marius/miniconda3/envs/ccai2022/lib/python3.10/site-packages/urllib3/connectionpool.py\", line 398, in _make_request\n    conn.request(method, url, **httplib_request_kw)\n  File \"/home/marius/miniconda3/envs/ccai2022/lib/python3.10/site-packages/urllib3/connection.py\", line 239, in request\n    super(HTTPConnection, self).request(method, url, body=body, headers=headers)\n  File \"/home/marius/miniconda3/envs/ccai2022/lib/python3.10/http/client.py\", line 1282, in request\n    self._send_request(method, url, body, headers, encode_chunked)\n  File \"/home/marius/miniconda3/envs/ccai2022/lib/python3.10/http/client.py\", line 1328, in _send_request\n    self.endheaders(body, encode_chunked=encode_chunked)\n  File \"/home/marius/miniconda3/envs/ccai2022/lib/python3.10/http/client.py\", line 1277, in endheaders\n    self._send_output(message_body, encode_chunked=encode_chunked)\n  File \"/home/marius/miniconda3/envs/ccai2022/lib/python3.10/http/client.py\", line 1037, in _send_output\n    self.send(msg)\n  File \"/home/marius/miniconda3/envs/ccai2022/lib/python3.10/http/client.py\", line 975, in send\n    self.connect()\n  File \"/home/marius/miniconda3/envs/ccai2022/lib/python3.10/site-packages/urllib3/connection.py\", line 205, in connect\n    conn = self._new_conn()\n  File \"/home/marius/miniconda3/envs/ccai2022/lib/python3.10/site-packages/urllib3/connection.py\", line 186, in _new_conn\n    raise NewConnectionError(\nurllib3.exceptions.NewConnectionError: <urllib3.connection.HTTPConnection object at 0x7f0b18ad62c0>: Failed to establish a new connection: [Errno 111] Connection refused\n\nDuring handling of the above exception, another exception occurred:\n\nTraceback (most recent call last):\n  File \"/home/marius/miniconda3/envs/ccai2022/lib/python3.10/site-packages/requests/adapters.py\", line 440, in send\n    resp = conn.urlopen(\n  File \"/home/marius/miniconda3/envs/ccai2022/lib/python3.10/site-packages/urllib3/connectionpool.py\", line 785, in urlopen\n    retries = retries.increment(\n  File \"/home/marius/miniconda3/envs/ccai2022/lib/python3.10/site-packages/urllib3/util/retry.py\", line 592, in increment\n    raise MaxRetryError(_pool, url, error or ResponseError(cause))\nurllib3.exceptions.MaxRetryError: HTTPConnectionPool(host='127.0.0.1', port=5000): Max retries exceeded with url: /name (Caused by NewConnectionError('<urllib3.connection.HTTPConnection object at 0x7f0b18ad62c0>: Failed to establish a new connection: [Errno 111] Connection refused'))\n\nDuring handling of the above exception, another exception occurred:\n\nTraceback (most recent call last):\n  File \"/home/marius/Desktop/project1-boptest-gym/testing/test_boptestGymEnv.py\", line 277, in test_DQN_D\n    self.partial_test_RL(case='D', algorithm='DQN')\n  File \"/home/marius/Desktop/project1-boptest-gym/testing/test_boptestGymEnv.py\", line 212, in partial_test_RL\n    env, model, start_time_tests, _ = train_RL.train_RL(algorithm=algorithm,\n  File \"/home/marius/Desktop/project1-boptest-gym/examples/train_RL.py\", line 173, in train_RL\n    env = BoptestGymEnvCustomReward(\n  File \"/home/marius/Desktop/project1-boptest-gym/boptestGymEnv.py\", line 164, in __init__\n    self.name = requests.get('{0}/name'.format(url)).json()['payload']\n  File \"/home/marius/miniconda3/envs/ccai2022/lib/python3.10/site-packages/requests/api.py\", line 75, in get\n    return request('get', url, params=params, **kwargs)\n  File \"/home/marius/miniconda3/envs/ccai2022/lib/python3.10/site-packages/requests/api.py\", line 61, in request\n    return session.request(method=method, url=url, **kwargs)\n  File \"/home/marius/miniconda3/envs/ccai2022/lib/python3.10/site-packages/requests/sessions.py\", line 529, in request\n    resp = self.send(prep, **send_kwargs)\n  File \"/home/marius/miniconda3/envs/ccai2022/lib/python3.10/site-packages/requests/sessions.py\", line 645, in send\n    r = adapter.send(request, **kwargs)\n  File \"/home/marius/miniconda3/envs/ccai2022/lib/python3.10/site-packages/requests/adapters.py\", line 519, in send\n    raise ConnectionError(e, request=request)\nrequests.exceptions.ConnectionError: HTTPConnectionPool(host='127.0.0.1', port=5000): Max retries exceeded with url: /name (Caused by NewConnectionError('<urllib3.connection.HTTPConnection object at 0x7f0b18ad62c0>: Failed to establish a new connection: [Errno 111] Connection refused'))\n", "5": "Traceback (most recent call last):\n  File \"/home/marius/miniconda3/envs/ccai2022/lib/python3.10/site-packages/urllib3/connection.py\", line 174, in _new_conn\n    conn = connection.create_connection(\n  File \"/home/marius/miniconda3/envs/ccai2022/lib/python3.10/site-packages/urllib3/util/connection.py\", line 95, in create_connection\n    raise err\n  File \"/home/marius/miniconda3/envs/ccai2022/lib/python3.10/site-packages/urllib3/util/connection.py\", line 85, in create_connection\n    sock.connect(sa)\nConnectionRefusedError: [Errno 111] Connection refused\n\nDuring handling of the above exception, another exception occurred:\n\nTraceback (most recent call last):\n  File \"/home/marius/miniconda3/envs/ccai2022/lib/python3.10/site-packages/urllib3/connectionpool.py\", line 703, in urlopen\n    httplib_response = self._make_request(\n  File \"/home/marius/miniconda3/envs/ccai2022/lib/python3.10/site-packages/urllib3/connectionpool.py\", line 398, in _make_request\n    conn.request(method, url, **httplib_request_kw)\n  File \"/home/marius/miniconda3/envs/ccai2022/lib/python3.10/site-packages/urllib3/connection.py\", line 239, in request\n    super(HTTPConnection, self).request(method, url, body=body, headers=headers)\n  File \"/home/marius/miniconda3/envs/ccai2022/lib/python3.10/http/client.py\", line 1282, in request\n    self._send_request(method, url, body, headers, encode_chunked)\n  File \"/home/marius/miniconda3/envs/ccai2022/lib/python3.10/http/client.py\", line 1328, in _send_request\n    self.endheaders(body, encode_chunked=encode_chunked)\n  File \"/home/marius/miniconda3/envs/ccai2022/lib/python3.10/http/client.py\", line 1277, in endheaders\n    self._send_output(message_body, encode_chunked=encode_chunked)\n  File \"/home/marius/miniconda3/envs/ccai2022/lib/python3.10/http/client.py\", line 1037, in _send_output\n    self.send(msg)\n  File \"/home/marius/miniconda3/envs/ccai2022/lib/python3.10/http/client.py\", line 975, in send\n    self.connect()\n  File \"/home/marius/miniconda3/envs/ccai2022/lib/python3.10/site-packages/urllib3/connection.py\", line 205, in connect\n    conn = self._new_conn()\n  File \"/home/marius/miniconda3/envs/ccai2022/lib/python3.10/site-packages/urllib3/connection.py\", line 186, in _new_conn\n    raise NewConnectionError(\nurllib3.exceptions.NewConnectionError: <urllib3.connection.HTTPConnection object at 0x7f0b18ad5cf0>: Failed to establish a new connection: [Errno 111] Connection refused\n\nDuring handling of the above exception, another exception occurred:\n\nTraceback (most recent call last):\n  File \"/home/marius/miniconda3/envs/ccai2022/lib/python3.10/site-packages/requests/adapters.py\", line 440, in send\n    resp = conn.urlopen(\n  File \"/home/marius/miniconda3/envs/ccai2022/lib/python3.10/site-packages/urllib3/connectionpool.py\", line 785, in urlopen\n    retries = retries.increment(\n  File \"/home/marius/miniconda3/envs/ccai2022/lib/python3.10/site-packages/urllib3/util/retry.py\", line 592, in increment\n    raise MaxRetryError(_pool, url, error or ResponseError(cause))\nurllib3.exceptions.MaxRetryError: HTTPConnectionPool(host='127.0.0.1', port=5000): Max retries exceeded with url: /name (Caused by NewConnectionError('<urllib3.connection.HTTPConnection object at 0x7f0b18ad5cf0>: Failed to establish a new connection: [Errno 111] Connection refused'))\n\nDuring handling of the above exception, another exception occurred:\n\nTraceback (most recent call last):\n  File \"/home/marius/Desktop/project1-boptest-gym/testing/test_boptestGymEnv.py\", line 289, in test_behavior_cloning_cont\n    self.partial_test_RL(case='D', algorithm='A2C', mode='train',\n  File \"/home/marius/Desktop/project1-boptest-gym/testing/test_boptestGymEnv.py\", line 212, in partial_test_RL\n    env, model, start_time_tests, _ = train_RL.train_RL(algorithm=algorithm,\n  File \"/home/marius/Desktop/project1-boptest-gym/examples/train_RL.py\", line 173, in train_RL\n    env = BoptestGymEnvCustomReward(\n  File \"/home/marius/Desktop/project1-boptest-gym/boptestGymEnv.py\", line 164, in __init__\n    self.name = requests.get('{0}/name'.format(url)).json()['payload']\n  File \"/home/marius/miniconda3/envs/ccai2022/lib/python3.10/site-packages/requests/api.py\", line 75, in get\n    return request('get', url, params=params, **kwargs)\n  File \"/home/marius/miniconda3/envs/ccai2022/lib/python3.10/site-packages/requests/api.py\", line 61, in request\n    return session.request(method=method, url=url, **kwargs)\n  File \"/home/marius/miniconda3/envs/ccai2022/lib/python3.10/site-packages/requests/sessions.py\", line 529, in request\n    resp = self.send(prep, **send_kwargs)\n  File \"/home/marius/miniconda3/envs/ccai2022/lib/python3.10/site-packages/requests/sessions.py\", line 645, in send\n    r = adapter.send(request, **kwargs)\n  File \"/home/marius/miniconda3/envs/ccai2022/lib/python3.10/site-packages/requests/adapters.py\", line 519, in send\n    raise ConnectionError(e, request=request)\nrequests.exceptions.ConnectionError: HTTPConnectionPool(host='127.0.0.1', port=5000): Max retries exceeded with url: /name (Caused by NewConnectionError('<urllib3.connection.HTTPConnection object at 0x7f0b18ad5cf0>: Failed to establish a new connection: [Errno 111] Connection refused'))\n", "6": "Traceback (most recent call last):\n  File \"/home/marius/miniconda3/envs/ccai2022/lib/python3.10/site-packages/urllib3/connection.py\", line 174, in _new_conn\n    conn = connection.create_connection(\n  File \"/home/marius/miniconda3/envs/ccai2022/lib/python3.10/site-packages/urllib3/util/connection.py\", line 95, in create_connection\n    raise err\n  File \"/home/marius/miniconda3/envs/ccai2022/lib/python3.10/site-packages/urllib3/util/connection.py\", line 85, in create_connection\n    sock.connect(sa)\nConnectionRefusedError: [Errno 111] Connection refused\n\nDuring handling of the above exception, another exception occurred:\n\nTraceback (most recent call last):\n  File \"/home/marius/miniconda3/envs/ccai2022/lib/python3.10/site-packages/urllib3/connectionpool.py\", line 703, in urlopen\n    httplib_response = self._make_request(\n  File \"/home/marius/miniconda3/envs/ccai2022/lib/python3.10/site-packages/urllib3/connectionpool.py\", line 398, in _make_request\n    conn.request(method, url, **httplib_request_kw)\n  File \"/home/marius/miniconda3/envs/ccai2022/lib/python3.10/site-packages/urllib3/connection.py\", line 239, in request\n    super(HTTPConnection, self).request(method, url, body=body, headers=headers)\n  File \"/home/marius/miniconda3/envs/ccai2022/lib/python3.10/http/client.py\", line 1282, in request\n    self._send_request(method, url, body, headers, encode_chunked)\n  File \"/home/marius/miniconda3/envs/ccai2022/lib/python3.10/http/client.py\", line 1328, in _send_request\n    self.endheaders(body, encode_chunked=encode_chunked)\n  File \"/home/marius/miniconda3/envs/ccai2022/lib/python3.10/http/client.py\", line 1277, in endheaders\n    self._send_output(message_body, encode_chunked=encode_chunked)\n  File \"/home/marius/miniconda3/envs/ccai2022/lib/python3.10/http/client.py\", line 1037, in _send_output\n    self.send(msg)\n  File \"/home/marius/miniconda3/envs/ccai2022/lib/python3.10/http/client.py\", line 975, in send\n    self.connect()\n  File \"/home/marius/miniconda3/envs/ccai2022/lib/python3.10/site-packages/urllib3/connection.py\", line 205, in connect\n    conn = self._new_conn()\n  File \"/home/marius/miniconda3/envs/ccai2022/lib/python3.10/site-packages/urllib3/connection.py\", line 186, in _new_conn\n    raise NewConnectionError(\nurllib3.exceptions.NewConnectionError: <urllib3.connection.HTTPConnection object at 0x7f0b18ad4f70>: Failed to establish a new connection: [Errno 111] Connection refused\n\nDuring handling of the above exception, another exception occurred:\n\nTraceback (most recent call last):\n  File \"/home/marius/miniconda3/envs/ccai2022/lib/python3.10/site-packages/requests/adapters.py\", line 440, in send\n    resp = conn.urlopen(\n  File \"/home/marius/miniconda3/envs/ccai2022/lib/python3.10/site-packages/urllib3/connectionpool.py\", line 785, in urlopen\n    retries = retries.increment(\n  File \"/home/marius/miniconda3/envs/ccai2022/lib/python3.10/site-packages/urllib3/util/retry.py\", line 592, in increment\n    raise MaxRetryError(_pool, url, error or ResponseError(cause))\nurllib3.exceptions.MaxRetryError: HTTPConnectionPool(host='127.0.0.1', port=5000): Max retries exceeded with url: /name (Caused by NewConnectionError('<urllib3.connection.HTTPConnection object at 0x7f0b18ad4f70>: Failed to establish a new connection: [Errno 111] Connection refused'))\n\nDuring handling of the above exception, another exception occurred:\n\nTraceback (most recent call last):\n  File \"/home/marius/Desktop/project1-boptest-gym/testing/test_boptestGymEnv.py\", line 303, in test_behavior_cloning_disc\n    self.partial_test_RL(case='D', algorithm='DQN', mode='train',\n  File \"/home/marius/Desktop/project1-boptest-gym/testing/test_boptestGymEnv.py\", line 212, in partial_test_RL\n    env, model, start_time_tests, _ = train_RL.train_RL(algorithm=algorithm,\n  File \"/home/marius/Desktop/project1-boptest-gym/examples/train_RL.py\", line 173, in train_RL\n    env = BoptestGymEnvCustomReward(\n  File \"/home/marius/Desktop/project1-boptest-gym/boptestGymEnv.py\", line 164, in __init__\n    self.name = requests.get('{0}/name'.format(url)).json()['payload']\n  File \"/home/marius/miniconda3/envs/ccai2022/lib/python3.10/site-packages/requests/api.py\", line 75, in get\n    return request('get', url, params=params, **kwargs)\n  File \"/home/marius/miniconda3/envs/ccai2022/lib/python3.10/site-packages/requests/api.py\", line 61, in request\n    return session.request(method=method, url=url, **kwargs)\n  File \"/home/marius/miniconda3/envs/ccai2022/lib/python3.10/site-packages/requests/sessions.py\", line 529, in request\n    resp = self.send(prep, **send_kwargs)\n  File \"/home/marius/miniconda3/envs/ccai2022/lib/python3.10/site-packages/requests/sessions.py\", line 645, in send\n    r = adapter.send(request, **kwargs)\n  File \"/home/marius/miniconda3/envs/ccai2022/lib/python3.10/site-packages/requests/adapters.py\", line 519, in send\n    raise ConnectionError(e, request=request)\nrequests.exceptions.ConnectionError: HTTPConnectionPool(host='127.0.0.1', port=5000): Max retries exceeded with url: /name (Caused by NewConnectionError('<urllib3.connection.HTTPConnection object at 0x7f0b18ad4f70>: Failed to establish a new connection: [Errno 111] Connection refused'))\n", "7": "Traceback (most recent call last):\n  File \"/home/marius/miniconda3/envs/ccai2022/lib/python3.10/site-packages/urllib3/connection.py\", line 174, in _new_conn\n    conn = connection.create_connection(\n  File \"/home/marius/miniconda3/envs/ccai2022/lib/python3.10/site-packages/urllib3/util/connection.py\", line 95, in create_connection\n    raise err\n  File \"/home/marius/miniconda3/envs/ccai2022/lib/python3.10/site-packages/urllib3/util/connection.py\", line 85, in create_connection\n    sock.connect(sa)\nConnectionRefusedError: [Errno 111] Connection refused\n\nDuring handling of the above exception, another exception occurred:\n\nTraceback (most recent call last):\n  File \"/home/marius/miniconda3/envs/ccai2022/lib/python3.10/site-packages/urllib3/connectionpool.py\", line 703, in urlopen\n    httplib_response = self._make_request(\n  File \"/home/marius/miniconda3/envs/ccai2022/lib/python3.10/site-packages/urllib3/connectionpool.py\", line 398, in _make_request\n    conn.request(method, url, **httplib_request_kw)\n  File \"/home/marius/miniconda3/envs/ccai2022/lib/python3.10/site-packages/urllib3/connection.py\", line 239, in request\n    super(HTTPConnection, self).request(method, url, body=body, headers=headers)\n  File \"/home/marius/miniconda3/envs/ccai2022/lib/python3.10/http/client.py\", line 1282, in request\n    self._send_request(method, url, body, headers, encode_chunked)\n  File \"/home/marius/miniconda3/envs/ccai2022/lib/python3.10/http/client.py\", line 1328, in _send_request\n    self.endheaders(body, encode_chunked=encode_chunked)\n  File \"/home/marius/miniconda3/envs/ccai2022/lib/python3.10/http/client.py\", line 1277, in endheaders\n    self._send_output(message_body, encode_chunked=encode_chunked)\n  File \"/home/marius/miniconda3/envs/ccai2022/lib/python3.10/http/client.py\", line 1037, in _send_output\n    self.send(msg)\n  File \"/home/marius/miniconda3/envs/ccai2022/lib/python3.10/http/client.py\", line 975, in send\n    self.connect()\n  File \"/home/marius/miniconda3/envs/ccai2022/lib/python3.10/site-packages/urllib3/connection.py\", line 205, in connect\n    conn = self._new_conn()\n  File \"/home/marius/miniconda3/envs/ccai2022/lib/python3.10/site-packages/urllib3/connection.py\", line 186, in _new_conn\n    raise NewConnectionError(\nurllib3.exceptions.NewConnectionError: <urllib3.connection.HTTPConnection object at 0x7f0b18ad7c70>: Failed to establish a new connection: [Errno 111] Connection refused\n\nDuring handling of the above exception, another exception occurred:\n\nTraceback (most recent call last):\n  File \"/home/marius/miniconda3/envs/ccai2022/lib/python3.10/site-packages/requests/adapters.py\", line 440, in send\n    resp = conn.urlopen(\n  File \"/home/marius/miniconda3/envs/ccai2022/lib/python3.10/site-packages/urllib3/connectionpool.py\", line 785, in urlopen\n    retries = retries.increment(\n  File \"/home/marius/miniconda3/envs/ccai2022/lib/python3.10/site-packages/urllib3/util/retry.py\", line 592, in increment\n    raise MaxRetryError(_pool, url, error or ResponseError(cause))\nurllib3.exceptions.MaxRetryError: HTTPConnectionPool(host='127.0.0.1', port=5000): Max retries exceeded with url: /name (Caused by NewConnectionError('<urllib3.connection.HTTPConnection object at 0x7f0b18ad7c70>: Failed to establish a new connection: [Errno 111] Connection refused'))\n\nDuring handling of the above exception, another exception occurred:\n\nTraceback (most recent call last):\n  File \"/home/marius/Desktop/project1-boptest-gym/testing/test_boptestGymEnv.py\", line 155, in test_compute_reward_clipping\n    obs, _, rew = run_baseline.run_reward_clipping(plot=False)\n  File \"/home/marius/Desktop/project1-boptest-gym/examples/run_baseline.py\", line 143, in run_reward_clipping\n    observations, actions, rewards = run(envClass=BoptestGymEnvClipping, plot=plot)\n  File \"/home/marius/Desktop/project1-boptest-gym/examples/run_baseline.py\", line 228, in run\n    env = envClass(url                 = url,\n  File \"/home/marius/Desktop/project1-boptest-gym/boptestGymEnv.py\", line 164, in __init__\n    self.name = requests.get('{0}/name'.format(url)).json()['payload']\n  File \"/home/marius/miniconda3/envs/ccai2022/lib/python3.10/site-packages/requests/api.py\", line 75, in get\n    return request('get', url, params=params, **kwargs)\n  File \"/home/marius/miniconda3/envs/ccai2022/lib/python3.10/site-packages/requests/api.py\", line 61, in request\n    return session.request(method=method, url=url, **kwargs)\n  File \"/home/marius/miniconda3/envs/ccai2022/lib/python3.10/site-packages/requests/sessions.py\", line 529, in request\n    resp = self.send(prep, **send_kwargs)\n  File \"/home/marius/miniconda3/envs/ccai2022/lib/python3.10/site-packages/requests/sessions.py\", line 645, in send\n    r = adapter.send(request, **kwargs)\n  File \"/home/marius/miniconda3/envs/ccai2022/lib/python3.10/site-packages/requests/adapters.py\", line 519, in send\n    raise ConnectionError(e, request=request)\nrequests.exceptions.ConnectionError: HTTPConnectionPool(host='127.0.0.1', port=5000): Max retries exceeded with url: /name (Caused by NewConnectionError('<urllib3.connection.HTTPConnection object at 0x7f0b18ad7c70>: Failed to establish a new connection: [Errno 111] Connection refused'))\n", "8": "Traceback (most recent call last):\n  File \"/home/marius/miniconda3/envs/ccai2022/lib/python3.10/site-packages/urllib3/connection.py\", line 174, in _new_conn\n    conn = connection.create_connection(\n  File \"/home/marius/miniconda3/envs/ccai2022/lib/python3.10/site-packages/urllib3/util/connection.py\", line 95, in create_connection\n    raise err\n  File \"/home/marius/miniconda3/envs/ccai2022/lib/python3.10/site-packages/urllib3/util/connection.py\", line 85, in create_connection\n    sock.connect(sa)\nConnectionRefusedError: [Errno 111] Connection refused\n\nDuring handling of the above exception, another exception occurred:\n\nTraceback (most recent call last):\n  File \"/home/marius/miniconda3/envs/ccai2022/lib/python3.10/site-packages/urllib3/connectionpool.py\", line 703, in urlopen\n    httplib_response = self._make_request(\n  File \"/home/marius/miniconda3/envs/ccai2022/lib/python3.10/site-packages/urllib3/connectionpool.py\", line 398, in _make_request\n    conn.request(method, url, **httplib_request_kw)\n  File \"/home/marius/miniconda3/envs/ccai2022/lib/python3.10/site-packages/urllib3/connection.py\", line 239, in request\n    super(HTTPConnection, self).request(method, url, body=body, headers=headers)\n  File \"/home/marius/miniconda3/envs/ccai2022/lib/python3.10/http/client.py\", line 1282, in request\n    self._send_request(method, url, body, headers, encode_chunked)\n  File \"/home/marius/miniconda3/envs/ccai2022/lib/python3.10/http/client.py\", line 1328, in _send_request\n    self.endheaders(body, encode_chunked=encode_chunked)\n  File \"/home/marius/miniconda3/envs/ccai2022/lib/python3.10/http/client.py\", line 1277, in endheaders\n    self._send_output(message_body, encode_chunked=encode_chunked)\n  File \"/home/marius/miniconda3/envs/ccai2022/lib/python3.10/http/client.py\", line 1037, in _send_output\n    self.send(msg)\n  File \"/home/marius/miniconda3/envs/ccai2022/lib/python3.10/http/client.py\", line 975, in send\n    self.connect()\n  File \"/home/marius/miniconda3/envs/ccai2022/lib/python3.10/site-packages/urllib3/connection.py\", line 205, in connect\n    conn = self._new_conn()\n  File \"/home/marius/miniconda3/envs/ccai2022/lib/python3.10/site-packages/urllib3/connection.py\", line 186, in _new_conn\n    raise NewConnectionError(\nurllib3.exceptions.NewConnectionError: <urllib3.connection.HTTPConnection object at 0x7f0b18ad62c0>: Failed to establish a new connection: [Errno 111] Connection refused\n\nDuring handling of the above exception, another exception occurred:\n\nTraceback (most recent call last):\n  File \"/home/marius/miniconda3/envs/ccai2022/lib/python3.10/site-packages/requests/adapters.py\", line 440, in send\n    resp = conn.urlopen(\n  File \"/home/marius/miniconda3/envs/ccai2022/lib/python3.10/site-packages/urllib3/connectionpool.py\", line 785, in urlopen\n    retries = retries.increment(\n  File \"/home/marius/miniconda3/envs/ccai2022/lib/python3.10/site-packages/urllib3/util/retry.py\", line 592, in increment\n    raise MaxRetryError(_pool, url, error or ResponseError(cause))\nurllib3.exceptions.MaxRetryError: HTTPConnectionPool(host='127.0.0.1', port=5000): Max retries exceeded with url: /name (Caused by NewConnectionError('<urllib3.connection.HTTPConnection object at 0x7f0b18ad62c0>: Failed to establish a new connection: [Errno 111] Connection refused'))\n\nDuring handling of the above exception, another exception occurred:\n\nTraceback (most recent call last):\n  File \"/home/marius/Desktop/project1-boptest-gym/testing/test_boptestGymEnv.py\", line 148, in test_compute_reward_custom\n    obs, _, rew = run_baseline.run_reward_custom(plot=False)\n  File \"/home/marius/Desktop/project1-boptest-gym/examples/run_baseline.py\", line 92, in run_reward_custom\n    observations, actions, rewards = run(envClass=BoptestGymEnvCustom, plot=plot)\n  File \"/home/marius/Desktop/project1-boptest-gym/examples/run_baseline.py\", line 228, in run\n    env = envClass(url                 = url,\n  File \"/home/marius/Desktop/project1-boptest-gym/boptestGymEnv.py\", line 164, in __init__\n    self.name = requests.get('{0}/name'.format(url)).json()['payload']\n  File \"/home/marius/miniconda3/envs/ccai2022/lib/python3.10/site-packages/requests/api.py\", line 75, in get\n    return request('get', url, params=params, **kwargs)\n  File \"/home/marius/miniconda3/envs/ccai2022/lib/python3.10/site-packages/requests/api.py\", line 61, in request\n    return session.request(method=method, url=url, **kwargs)\n  File \"/home/marius/miniconda3/envs/ccai2022/lib/python3.10/site-packages/requests/sessions.py\", line 529, in request\n    resp = self.send(prep, **send_kwargs)\n  File \"/home/marius/miniconda3/envs/ccai2022/lib/python3.10/site-packages/requests/sessions.py\", line 645, in send\n    r = adapter.send(request, **kwargs)\n  File \"/home/marius/miniconda3/envs/ccai2022/lib/python3.10/site-packages/requests/adapters.py\", line 519, in send\n    raise ConnectionError(e, request=request)\nrequests.exceptions.ConnectionError: HTTPConnectionPool(host='127.0.0.1', port=5000): Max retries exceeded with url: /name (Caused by NewConnectionError('<urllib3.connection.HTTPConnection object at 0x7f0b18ad62c0>: Failed to establish a new connection: [Errno 111] Connection refused'))\n", "9": "Traceback (most recent call last):\n  File \"/home/marius/miniconda3/envs/ccai2022/lib/python3.10/site-packages/urllib3/connection.py\", line 174, in _new_conn\n    conn = connection.create_connection(\n  File \"/home/marius/miniconda3/envs/ccai2022/lib/python3.10/site-packages/urllib3/util/connection.py\", line 95, in create_connection\n    raise err\n  File \"/home/marius/miniconda3/envs/ccai2022/lib/python3.10/site-packages/urllib3/util/connection.py\", line 85, in create_connection\n    sock.connect(sa)\nConnectionRefusedError: [Errno 111] Connection refused\n\nDuring handling of the above exception, another exception occurred:\n\nTraceback (most recent call last):\n  File \"/home/marius/miniconda3/envs/ccai2022/lib/python3.10/site-packages/urllib3/connectionpool.py\", line 703, in urlopen\n    httplib_response = self._make_request(\n  File \"/home/marius/miniconda3/envs/ccai2022/lib/python3.10/site-packages/urllib3/connectionpool.py\", line 398, in _make_request\n    conn.request(method, url, **httplib_request_kw)\n  File \"/home/marius/miniconda3/envs/ccai2022/lib/python3.10/site-packages/urllib3/connection.py\", line 239, in request\n    super(HTTPConnection, self).request(method, url, body=body, headers=headers)\n  File \"/home/marius/miniconda3/envs/ccai2022/lib/python3.10/http/client.py\", line 1282, in request\n    self._send_request(method, url, body, headers, encode_chunked)\n  File \"/home/marius/miniconda3/envs/ccai2022/lib/python3.10/http/client.py\", line 1328, in _send_request\n    self.endheaders(body, encode_chunked=encode_chunked)\n  File \"/home/marius/miniconda3/envs/ccai2022/lib/python3.10/http/client.py\", line 1277, in endheaders\n    self._send_output(message_body, encode_chunked=encode_chunked)\n  File \"/home/marius/miniconda3/envs/ccai2022/lib/python3.10/http/client.py\", line 1037, in _send_output\n    self.send(msg)\n  File \"/home/marius/miniconda3/envs/ccai2022/lib/python3.10/http/client.py\", line 975, in send\n    self.connect()\n  File \"/home/marius/miniconda3/envs/ccai2022/lib/python3.10/site-packages/urllib3/connection.py\", line 205, in connect\n    conn = self._new_conn()\n  File \"/home/marius/miniconda3/envs/ccai2022/lib/python3.10/site-packages/urllib3/connection.py\", line 186, in _new_conn\n    raise NewConnectionError(\nurllib3.exceptions.NewConnectionError: <urllib3.connection.HTTPConnection object at 0x7f0b18ad41c0>: Failed to establish a new connection: [Errno 111] Connection refused\n\nDuring handling of the above exception, another exception occurred:\n\nTraceback (most recent call last):\n  File \"/home/marius/miniconda3/envs/ccai2022/lib/python3.10/site-packages/requests/adapters.py\", line 440, in send\n    resp = conn.urlopen(\n  File \"/home/marius/miniconda3/envs/ccai2022/lib/python3.10/site-packages/urllib3/connectionpool.py\", line 785, in urlopen\n    retries = retries.increment(\n  File \"/home/marius/miniconda3/envs/ccai2022/lib/python3.10/site-packages/urllib3/util/retry.py\", line 592, in increment\n    raise MaxRetryError(_pool, url, error or ResponseError(cause))\nurllib3.exceptions.MaxRetryError: HTTPConnectionPool(host='127.0.0.1', port=5000): Max retries exceeded with url: /name (Caused by NewConnectionError('<urllib3.connection.HTTPConnection object at 0x7f0b18ad41c0>: Failed to establish a new connection: [Errno 111] Connection refused'))\n\nDuring handling of the above exception, another exception occurred:\n\nTraceback (most recent call last):\n  File \"/home/marius/Desktop/project1-boptest-gym/testing/test_boptestGymEnv.py\", line 141, in test_compute_reward_default\n    obs, _, rew = run_baseline.run_reward_default(plot=False)\n  File \"/home/marius/Desktop/project1-boptest-gym/examples/run_baseline.py\", line 43, in run_reward_default\n    observations, actions, rewards = run(envClass=BoptestGymEnv, plot=plot)\n  File \"/home/marius/Desktop/project1-boptest-gym/examples/run_baseline.py\", line 228, in run\n    env = envClass(url                 = url,\n  File \"/home/marius/Desktop/project1-boptest-gym/boptestGymEnv.py\", line 164, in __init__\n    self.name = requests.get('{0}/name'.format(url)).json()['payload']\n  File \"/home/marius/miniconda3/envs/ccai2022/lib/python3.10/site-packages/requests/api.py\", line 75, in get\n    return request('get', url, params=params, **kwargs)\n  File \"/home/marius/miniconda3/envs/ccai2022/lib/python3.10/site-packages/requests/api.py\", line 61, in request\n    return session.request(method=method, url=url, **kwargs)\n  File \"/home/marius/miniconda3/envs/ccai2022/lib/python3.10/site-packages/requests/sessions.py\", line 529, in request\n    resp = self.send(prep, **send_kwargs)\n  File \"/home/marius/miniconda3/envs/ccai2022/lib/python3.10/site-packages/requests/sessions.py\", line 645, in send\n    r = adapter.send(request, **kwargs)\n  File \"/home/marius/miniconda3/envs/ccai2022/lib/python3.10/site-packages/requests/adapters.py\", line 519, in send\n    raise ConnectionError(e, request=request)\nrequests.exceptions.ConnectionError: HTTPConnectionPool(host='127.0.0.1', port=5000): Max retries exceeded with url: /name (Caused by NewConnectionError('<urllib3.connection.HTTPConnection object at 0x7f0b18ad41c0>: Failed to establish a new connection: [Errno 111] Connection refused'))\n", "10": "Traceback (most recent call last):\n  File \"/home/marius/miniconda3/envs/ccai2022/lib/python3.10/site-packages/urllib3/connection.py\", line 174, in _new_conn\n    conn = connection.create_connection(\n  File \"/home/marius/miniconda3/envs/ccai2022/lib/python3.10/site-packages/urllib3/util/connection.py\", line 95, in create_connection\n    raise err\n  File \"/home/marius/miniconda3/envs/ccai2022/lib/python3.10/site-packages/urllib3/util/connection.py\", line 85, in create_connection\n    sock.connect(sa)\nConnectionRefusedError: [Errno 111] Connection refused\n\nDuring handling of the above exception, another exception occurred:\n\nTraceback (most recent call last):\n  File \"/home/marius/miniconda3/envs/ccai2022/lib/python3.10/site-packages/urllib3/connectionpool.py\", line 703, in urlopen\n    httplib_response = self._make_request(\n  File \"/home/marius/miniconda3/envs/ccai2022/lib/python3.10/site-packages/urllib3/connectionpool.py\", line 398, in _make_request\n    conn.request(method, url, **httplib_request_kw)\n  File \"/home/marius/miniconda3/envs/ccai2022/lib/python3.10/site-packages/urllib3/connection.py\", line 239, in request\n    super(HTTPConnection, self).request(method, url, body=body, headers=headers)\n  File \"/home/marius/miniconda3/envs/ccai2022/lib/python3.10/http/client.py\", line 1282, in request\n    self._send_request(method, url, body, headers, encode_chunked)\n  File \"/home/marius/miniconda3/envs/ccai2022/lib/python3.10/http/client.py\", line 1328, in _send_request\n    self.endheaders(body, encode_chunked=encode_chunked)\n  File \"/home/marius/miniconda3/envs/ccai2022/lib/python3.10/http/client.py\", line 1277, in endheaders\n    self._send_output(message_body, encode_chunked=encode_chunked)\n  File \"/home/marius/miniconda3/envs/ccai2022/lib/python3.10/http/client.py\", line 1037, in _send_output\n    self.send(msg)\n  File \"/home/marius/miniconda3/envs/ccai2022/lib/python3.10/http/client.py\", line 975, in send\n    self.connect()\n  File \"/home/marius/miniconda3/envs/ccai2022/lib/python3.10/site-packages/urllib3/connection.py\", line 205, in connect\n    conn = self._new_conn()\n  File \"/home/marius/miniconda3/envs/ccai2022/lib/python3.10/site-packages/urllib3/connection.py\", line 186, in _new_conn\n    raise NewConnectionError(\nurllib3.exceptions.NewConnectionError: <urllib3.connection.HTTPConnection object at 0x7f0b18ad6ad0>: Failed to establish a new connection: [Errno 111] Connection refused\n\nDuring handling of the above exception, another exception occurred:\n\nTraceback (most recent call last):\n  File \"/home/marius/miniconda3/envs/ccai2022/lib/python3.10/site-packages/requests/adapters.py\", line 440, in send\n    resp = conn.urlopen(\n  File \"/home/marius/miniconda3/envs/ccai2022/lib/python3.10/site-packages/urllib3/connectionpool.py\", line 785, in urlopen\n    retries = retries.increment(\n  File \"/home/marius/miniconda3/envs/ccai2022/lib/python3.10/site-packages/urllib3/util/retry.py\", line 592, in increment\n    raise MaxRetryError(_pool, url, error or ResponseError(cause))\nurllib3.exceptions.MaxRetryError: HTTPConnectionPool(host='127.0.0.1', port=5000): Max retries exceeded with url: /name (Caused by NewConnectionError('<urllib3.connection.HTTPConnection object at 0x7f0b18ad6ad0>: Failed to establish a new connection: [Errno 111] Connection refused'))\n\nDuring handling of the above exception, another exception occurred:\n\nTraceback (most recent call last):\n  File \"/home/marius/Desktop/project1-boptest-gym/testing/test_boptestGymEnv.py\", line 169, in test_normalized_action_wrapper\n    obs, act, rew = run_sample.run_normalized_action_wrapper(plot=False)\n  File \"/home/marius/Desktop/project1-boptest-gym/examples/run_sample.py\", line 42, in run_normalized_action_wrapper\n    observations, actions, rewards = run(envClass=BoptestGymEnv,\n  File \"/home/marius/Desktop/project1-boptest-gym/examples/run_sample.py\", line 50, in run\n    env = envClass(url                 = url,\n  File \"/home/marius/Desktop/project1-boptest-gym/boptestGymEnv.py\", line 164, in __init__\n    self.name = requests.get('{0}/name'.format(url)).json()['payload']\n  File \"/home/marius/miniconda3/envs/ccai2022/lib/python3.10/site-packages/requests/api.py\", line 75, in get\n    return request('get', url, params=params, **kwargs)\n  File \"/home/marius/miniconda3/envs/ccai2022/lib/python3.10/site-packages/requests/api.py\", line 61, in request\n    return session.request(method=method, url=url, **kwargs)\n  File \"/home/marius/miniconda3/envs/ccai2022/lib/python3.10/site-packages/requests/sessions.py\", line 529, in request\n    resp = self.send(prep, **send_kwargs)\n  File \"/home/marius/miniconda3/envs/ccai2022/lib/python3.10/site-packages/requests/sessions.py\", line 645, in send\n    r = adapter.send(request, **kwargs)\n  File \"/home/marius/miniconda3/envs/ccai2022/lib/python3.10/site-packages/requests/adapters.py\", line 519, in send\n    raise ConnectionError(e, request=request)\nrequests.exceptions.ConnectionError: HTTPConnectionPool(host='127.0.0.1', port=5000): Max retries exceeded with url: /name (Caused by NewConnectionError('<urllib3.connection.HTTPConnection object at 0x7f0b18ad6ad0>: Failed to establish a new connection: [Errno 111] Connection refused'))\n", "11": "Traceback (most recent call last):\n  File \"/home/marius/miniconda3/envs/ccai2022/lib/python3.10/site-packages/urllib3/connection.py\", line 174, in _new_conn\n    conn = connection.create_connection(\n  File \"/home/marius/miniconda3/envs/ccai2022/lib/python3.10/site-packages/urllib3/util/connection.py\", line 95, in create_connection\n    raise err\n  File \"/home/marius/miniconda3/envs/ccai2022/lib/python3.10/site-packages/urllib3/util/connection.py\", line 85, in create_connection\n    sock.connect(sa)\nConnectionRefusedError: [Errno 111] Connection refused\n\nDuring handling of the above exception, another exception occurred:\n\nTraceback (most recent call last):\n  File \"/home/marius/miniconda3/envs/ccai2022/lib/python3.10/site-packages/urllib3/connectionpool.py\", line 703, in urlopen\n    httplib_response = self._make_request(\n  File \"/home/marius/miniconda3/envs/ccai2022/lib/python3.10/site-packages/urllib3/connectionpool.py\", line 398, in _make_request\n    conn.request(method, url, **httplib_request_kw)\n  File \"/home/marius/miniconda3/envs/ccai2022/lib/python3.10/site-packages/urllib3/connection.py\", line 239, in request\n    super(HTTPConnection, self).request(method, url, body=body, headers=headers)\n  File \"/home/marius/miniconda3/envs/ccai2022/lib/python3.10/http/client.py\", line 1282, in request\n    self._send_request(method, url, body, headers, encode_chunked)\n  File \"/home/marius/miniconda3/envs/ccai2022/lib/python3.10/http/client.py\", line 1328, in _send_request\n    self.endheaders(body, encode_chunked=encode_chunked)\n  File \"/home/marius/miniconda3/envs/ccai2022/lib/python3.10/http/client.py\", line 1277, in endheaders\n    self._send_output(message_body, encode_chunked=encode_chunked)\n  File \"/home/marius/miniconda3/envs/ccai2022/lib/python3.10/http/client.py\", line 1037, in _send_output\n    self.send(msg)\n  File \"/home/marius/miniconda3/envs/ccai2022/lib/python3.10/http/client.py\", line 975, in send\n    self.connect()\n  File \"/home/marius/miniconda3/envs/ccai2022/lib/python3.10/site-packages/urllib3/connection.py\", line 205, in connect\n    conn = self._new_conn()\n  File \"/home/marius/miniconda3/envs/ccai2022/lib/python3.10/site-packages/urllib3/connection.py\", line 186, in _new_conn\n    raise NewConnectionError(\nurllib3.exceptions.NewConnectionError: <urllib3.connection.HTTPConnection object at 0x7f0b18ad7640>: Failed to establish a new connection: [Errno 111] Connection refused\n\nDuring handling of the above exception, another exception occurred:\n\nTraceback (most recent call last):\n  File \"/home/marius/miniconda3/envs/ccai2022/lib/python3.10/site-packages/requests/adapters.py\", line 440, in send\n    resp = conn.urlopen(\n  File \"/home/marius/miniconda3/envs/ccai2022/lib/python3.10/site-packages/urllib3/connectionpool.py\", line 785, in urlopen\n    retries = retries.increment(\n  File \"/home/marius/miniconda3/envs/ccai2022/lib/python3.10/site-packages/urllib3/util/retry.py\", line 592, in increment\n    raise MaxRetryError(_pool, url, error or ResponseError(cause))\nurllib3.exceptions.MaxRetryError: HTTPConnectionPool(host='127.0.0.1', port=5000): Max retries exceeded with url: /name (Caused by NewConnectionError('<urllib3.connection.HTTPConnection object at 0x7f0b18ad7640>: Failed to establish a new connection: [Errno 111] Connection refused'))\n\nDuring handling of the above exception, another exception occurred:\n\nTraceback (most recent call last):\n  File \"/home/marius/Desktop/project1-boptest-gym/testing/test_boptestGymEnv.py\", line 162, in test_normalized_observation_wrapper\n    obs, _, rew = run_baseline.run_normalized_observation_wrapper(plot=False)\n  File \"/home/marius/Desktop/project1-boptest-gym/examples/run_baseline.py\", line 167, in run_normalized_observation_wrapper\n    observations, actions, rewards = run(envClass=BoptestGymEnv,\n  File \"/home/marius/Desktop/project1-boptest-gym/examples/run_baseline.py\", line 228, in run\n    env = envClass(url                 = url,\n  File \"/home/marius/Desktop/project1-boptest-gym/boptestGymEnv.py\", line 164, in __init__\n    self.name = requests.get('{0}/name'.format(url)).json()['payload']\n  File \"/home/marius/miniconda3/envs/ccai2022/lib/python3.10/site-packages/requests/api.py\", line 75, in get\n    return request('get', url, params=params, **kwargs)\n  File \"/home/marius/miniconda3/envs/ccai2022/lib/python3.10/site-packages/requests/api.py\", line 61, in request\n    return session.request(method=method, url=url, **kwargs)\n  File \"/home/marius/miniconda3/envs/ccai2022/lib/python3.10/site-packages/requests/sessions.py\", line 529, in request\n    resp = self.send(prep, **send_kwargs)\n  File \"/home/marius/miniconda3/envs/ccai2022/lib/python3.10/site-packages/requests/sessions.py\", line 645, in send\n    r = adapter.send(request, **kwargs)\n  File \"/home/marius/miniconda3/envs/ccai2022/lib/python3.10/site-packages/requests/adapters.py\", line 519, in send\n    raise ConnectionError(e, request=request)\nrequests.exceptions.ConnectionError: HTTPConnectionPool(host='127.0.0.1', port=5000): Max retries exceeded with url: /name (Caused by NewConnectionError('<urllib3.connection.HTTPConnection object at 0x7f0b18ad7640>: Failed to establish a new connection: [Errno 111] Connection refused'))\n", "12": "Traceback (most recent call last):\n  File \"/home/marius/miniconda3/envs/ccai2022/lib/python3.10/site-packages/urllib3/connection.py\", line 174, in _new_conn\n    conn = connection.create_connection(\n  File \"/home/marius/miniconda3/envs/ccai2022/lib/python3.10/site-packages/urllib3/util/connection.py\", line 95, in create_connection\n    raise err\n  File \"/home/marius/miniconda3/envs/ccai2022/lib/python3.10/site-packages/urllib3/util/connection.py\", line 85, in create_connection\n    sock.connect(sa)\nConnectionRefusedError: [Errno 111] Connection refused\n\nDuring handling of the above exception, another exception occurred:\n\nTraceback (most recent call last):\n  File \"/home/marius/miniconda3/envs/ccai2022/lib/python3.10/site-packages/urllib3/connectionpool.py\", line 703, in urlopen\n    httplib_response = self._make_request(\n  File \"/home/marius/miniconda3/envs/ccai2022/lib/python3.10/site-packages/urllib3/connectionpool.py\", line 398, in _make_request\n    conn.request(method, url, **httplib_request_kw)\n  File \"/home/marius/miniconda3/envs/ccai2022/lib/python3.10/site-packages/urllib3/connection.py\", line 239, in request\n    super(HTTPConnection, self).request(method, url, body=body, headers=headers)\n  File \"/home/marius/miniconda3/envs/ccai2022/lib/python3.10/http/client.py\", line 1282, in request\n    self._send_request(method, url, body, headers, encode_chunked)\n  File \"/home/marius/miniconda3/envs/ccai2022/lib/python3.10/http/client.py\", line 1328, in _send_request\n    self.endheaders(body, encode_chunked=encode_chunked)\n  File \"/home/marius/miniconda3/envs/ccai2022/lib/python3.10/http/client.py\", line 1277, in endheaders\n    self._send_output(message_body, encode_chunked=encode_chunked)\n  File \"/home/marius/miniconda3/envs/ccai2022/lib/python3.10/http/client.py\", line 1037, in _send_output\n    self.send(msg)\n  File \"/home/marius/miniconda3/envs/ccai2022/lib/python3.10/http/client.py\", line 975, in send\n    self.connect()\n  File \"/home/marius/miniconda3/envs/ccai2022/lib/python3.10/site-packages/urllib3/connection.py\", line 205, in connect\n    conn = self._new_conn()\n  File \"/home/marius/miniconda3/envs/ccai2022/lib/python3.10/site-packages/urllib3/connection.py\", line 186, in _new_conn\n    raise NewConnectionError(\nurllib3.exceptions.NewConnectionError: <urllib3.connection.HTTPConnection object at 0x7f0b18ad6470>: Failed to establish a new connection: [Errno 111] Connection refused\n\nDuring handling of the above exception, another exception occurred:\n\nTraceback (most recent call last):\n  File \"/home/marius/miniconda3/envs/ccai2022/lib/python3.10/site-packages/requests/adapters.py\", line 440, in send\n    resp = conn.urlopen(\n  File \"/home/marius/miniconda3/envs/ccai2022/lib/python3.10/site-packages/urllib3/connectionpool.py\", line 785, in urlopen\n    retries = retries.increment(\n  File \"/home/marius/miniconda3/envs/ccai2022/lib/python3.10/site-packages/urllib3/util/retry.py\", line 592, in increment\n    raise MaxRetryError(_pool, url, error or ResponseError(cause))\nurllib3.exceptions.MaxRetryError: HTTPConnectionPool(host='127.0.0.1', port=5000): Max retries exceeded with url: /name (Caused by NewConnectionError('<urllib3.connection.HTTPConnection object at 0x7f0b18ad6470>: Failed to establish a new connection: [Errno 111] Connection refused'))\n\nDuring handling of the above exception, another exception occurred:\n\nTraceback (most recent call last):\n  File \"/home/marius/Desktop/project1-boptest-gym/testing/test_boptestGymEnv.py\", line 321, in test_save_callback\n    env, _, _ = run_save_callback.train_A2C_with_callback(log_dir=log_dir,\n  File \"/home/marius/Desktop/project1-boptest-gym/examples/run_save_callback.py\", line 55, in train_A2C_with_callback\n    env = BoptestGymEnvRewardWeightCost(url                   = url,\n  File \"/home/marius/Desktop/project1-boptest-gym/boptestGymEnv.py\", line 164, in __init__\n    self.name = requests.get('{0}/name'.format(url)).json()['payload']\n  File \"/home/marius/miniconda3/envs/ccai2022/lib/python3.10/site-packages/requests/api.py\", line 75, in get\n    return request('get', url, params=params, **kwargs)\n  File \"/home/marius/miniconda3/envs/ccai2022/lib/python3.10/site-packages/requests/api.py\", line 61, in request\n    return session.request(method=method, url=url, **kwargs)\n  File \"/home/marius/miniconda3/envs/ccai2022/lib/python3.10/site-packages/requests/sessions.py\", line 529, in request\n    resp = self.send(prep, **send_kwargs)\n  File \"/home/marius/miniconda3/envs/ccai2022/lib/python3.10/site-packages/requests/sessions.py\", line 645, in send\n    r = adapter.send(request, **kwargs)\n  File \"/home/marius/miniconda3/envs/ccai2022/lib/python3.10/site-packages/requests/adapters.py\", line 519, in send\n    raise ConnectionError(e, request=request)\nrequests.exceptions.ConnectionError: HTTPConnectionPool(host='127.0.0.1', port=5000): Max retries exceeded with url: /name (Caused by NewConnectionError('<urllib3.connection.HTTPConnection object at 0x7f0b18ad6470>: Failed to establish a new connection: [Errno 111] Connection refused'))\n", "13": "Traceback (most recent call last):\n  File \"/home/marius/miniconda3/envs/ccai2022/lib/python3.10/site-packages/urllib3/connection.py\", line 174, in _new_conn\n    conn = connection.create_connection(\n  File \"/home/marius/miniconda3/envs/ccai2022/lib/python3.10/site-packages/urllib3/util/connection.py\", line 95, in create_connection\n    raise err\n  File \"/home/marius/miniconda3/envs/ccai2022/lib/python3.10/site-packages/urllib3/util/connection.py\", line 85, in create_connection\n    sock.connect(sa)\nConnectionRefusedError: [Errno 111] Connection refused\n\nDuring handling of the above exception, another exception occurred:\n\nTraceback (most recent call last):\n  File \"/home/marius/miniconda3/envs/ccai2022/lib/python3.10/site-packages/urllib3/connectionpool.py\", line 703, in urlopen\n    httplib_response = self._make_request(\n  File \"/home/marius/miniconda3/envs/ccai2022/lib/python3.10/site-packages/urllib3/connectionpool.py\", line 398, in _make_request\n    conn.request(method, url, **httplib_request_kw)\n  File \"/home/marius/miniconda3/envs/ccai2022/lib/python3.10/site-packages/urllib3/connection.py\", line 239, in request\n    super(HTTPConnection, self).request(method, url, body=body, headers=headers)\n  File \"/home/marius/miniconda3/envs/ccai2022/lib/python3.10/http/client.py\", line 1282, in request\n    self._send_request(method, url, body, headers, encode_chunked)\n  File \"/home/marius/miniconda3/envs/ccai2022/lib/python3.10/http/client.py\", line 1328, in _send_request\n    self.endheaders(body, encode_chunked=encode_chunked)\n  File \"/home/marius/miniconda3/envs/ccai2022/lib/python3.10/http/client.py\", line 1277, in endheaders\n    self._send_output(message_body, encode_chunked=encode_chunked)\n  File \"/home/marius/miniconda3/envs/ccai2022/lib/python3.10/http/client.py\", line 1037, in _send_output\n    self.send(msg)\n  File \"/home/marius/miniconda3/envs/ccai2022/lib/python3.10/http/client.py\", line 975, in send\n    self.connect()\n  File \"/home/marius/miniconda3/envs/ccai2022/lib/python3.10/site-packages/urllib3/connection.py\", line 205, in connect\n    conn = self._new_conn()\n  File \"/home/marius/miniconda3/envs/ccai2022/lib/python3.10/site-packages/urllib3/connection.py\", line 186, in _new_conn\n    raise NewConnectionError(\nurllib3.exceptions.NewConnectionError: <urllib3.connection.HTTPConnection object at 0x7f0b18ad6410>: Failed to establish a new connection: [Errno 111] Connection refused\n\nDuring handling of the above exception, another exception occurred:\n\nTraceback (most recent call last):\n  File \"/home/marius/miniconda3/envs/ccai2022/lib/python3.10/site-packages/requests/adapters.py\", line 440, in send\n    resp = conn.urlopen(\n  File \"/home/marius/miniconda3/envs/ccai2022/lib/python3.10/site-packages/urllib3/connectionpool.py\", line 785, in urlopen\n    retries = retries.increment(\n  File \"/home/marius/miniconda3/envs/ccai2022/lib/python3.10/site-packages/urllib3/util/retry.py\", line 592, in increment\n    raise MaxRetryError(_pool, url, error or ResponseError(cause))\nurllib3.exceptions.MaxRetryError: HTTPConnectionPool(host='127.0.0.1', port=5000): Max retries exceeded with url: /name (Caused by NewConnectionError('<urllib3.connection.HTTPConnection object at 0x7f0b18ad6410>: Failed to establish a new connection: [Errno 111] Connection refused'))\n\nDuring handling of the above exception, another exception occurred:\n\nTraceback (most recent call last):\n  File \"/home/marius/Desktop/project1-boptest-gym/testing/test_boptestGymEnv.py\", line 176, in test_set_scenario\n    obs, _, rew = run_baseline.run_highly_dynamic_price(plot=False)\n  File \"/home/marius/Desktop/project1-boptest-gym/examples/run_baseline.py\", line 219, in run_highly_dynamic_price\n    observations, actions, rewards = run(envClass=BoptestGymEnv,\n  File \"/home/marius/Desktop/project1-boptest-gym/examples/run_baseline.py\", line 228, in run\n    env = envClass(url                 = url,\n  File \"/home/marius/Desktop/project1-boptest-gym/boptestGymEnv.py\", line 164, in __init__\n    self.name = requests.get('{0}/name'.format(url)).json()['payload']\n  File \"/home/marius/miniconda3/envs/ccai2022/lib/python3.10/site-packages/requests/api.py\", line 75, in get\n    return request('get', url, params=params, **kwargs)\n  File \"/home/marius/miniconda3/envs/ccai2022/lib/python3.10/site-packages/requests/api.py\", line 61, in request\n    return session.request(method=method, url=url, **kwargs)\n  File \"/home/marius/miniconda3/envs/ccai2022/lib/python3.10/site-packages/requests/sessions.py\", line 529, in request\n    resp = self.send(prep, **send_kwargs)\n  File \"/home/marius/miniconda3/envs/ccai2022/lib/python3.10/site-packages/requests/sessions.py\", line 645, in send\n    r = adapter.send(request, **kwargs)\n  File \"/home/marius/miniconda3/envs/ccai2022/lib/python3.10/site-packages/requests/adapters.py\", line 519, in send\n    raise ConnectionError(e, request=request)\nrequests.exceptions.ConnectionError: HTTPConnectionPool(host='127.0.0.1', port=5000): Max retries exceeded with url: /name (Caused by NewConnectionError('<urllib3.connection.HTTPConnection object at 0x7f0b18ad6410>: Failed to establish a new connection: [Errno 111] Connection refused'))\n", "14": "Traceback (most recent call last):\n  File \"/home/marius/Desktop/project1-boptest-gym/testing/test_boptestGymEnv.py\", line 67, in test_summary\n    self.compare_ref_json(sorted(dict(summary[k])), file_ref+'_'+str(i)+'.json')\n  File \"/home/marius/Desktop/project1-boptest-gym/testing/utilities.py\", line 213, in compare_ref_json\n    with open(ref_filepath, 'w') as f:\nFileNotFoundError: [Errno 2] No such file or directory: 'references/summary_ref_0.json'\n", "15": "Traceback (most recent call last):\n  File \"/home/marius/miniconda3/envs/ccai2022/lib/python3.10/site-packages/urllib3/connection.py\", line 174, in _new_conn\n    conn = connection.create_connection(\n  File \"/home/marius/miniconda3/envs/ccai2022/lib/python3.10/site-packages/urllib3/util/connection.py\", line 95, in create_connection\n    raise err\n  File \"/home/marius/miniconda3/envs/ccai2022/lib/python3.10/site-packages/urllib3/util/connection.py\", line 85, in create_connection\n    sock.connect(sa)\nConnectionRefusedError: [Errno 111] Connection refused\n\nDuring handling of the above exception, another exception occurred:\n\nTraceback (most recent call last):\n  File \"/home/marius/miniconda3/envs/ccai2022/lib/python3.10/site-packages/urllib3/connectionpool.py\", line 703, in urlopen\n    httplib_response = self._make_request(\n  File \"/home/marius/miniconda3/envs/ccai2022/lib/python3.10/site-packages/urllib3/connectionpool.py\", line 398, in _make_request\n    conn.request(method, url, **httplib_request_kw)\n  File \"/home/marius/miniconda3/envs/ccai2022/lib/python3.10/site-packages/urllib3/connection.py\", line 239, in request\n    super(HTTPConnection, self).request(method, url, body=body, headers=headers)\n  File \"/home/marius/miniconda3/envs/ccai2022/lib/python3.10/http/client.py\", line 1282, in request\n    self._send_request(method, url, body, headers, encode_chunked)\n  File \"/home/marius/miniconda3/envs/ccai2022/lib/python3.10/http/client.py\", line 1328, in _send_request\n    self.endheaders(body, encode_chunked=encode_chunked)\n  File \"/home/marius/miniconda3/envs/ccai2022/lib/python3.10/http/client.py\", line 1277, in endheaders\n    self._send_output(message_body, encode_chunked=encode_chunked)\n  File \"/home/marius/miniconda3/envs/ccai2022/lib/python3.10/http/client.py\", line 1037, in _send_output\n    self.send(msg)\n  File \"/home/marius/miniconda3/envs/ccai2022/lib/python3.10/http/client.py\", line 975, in send\n    self.connect()\n  File \"/home/marius/miniconda3/envs/ccai2022/lib/python3.10/site-packages/urllib3/connection.py\", line 205, in connect\n    conn = self._new_conn()\n  File \"/home/marius/miniconda3/envs/ccai2022/lib/python3.10/site-packages/urllib3/connection.py\", line 186, in _new_conn\n    raise NewConnectionError(\nurllib3.exceptions.NewConnectionError: <urllib3.connection.HTTPConnection object at 0x7f0b18ad4400>: Failed to establish a new connection: [Errno 111] Connection refused\n\nDuring handling of the above exception, another exception occurred:\n\nTraceback (most recent call last):\n  File \"/home/marius/miniconda3/envs/ccai2022/lib/python3.10/site-packages/requests/adapters.py\", line 440, in send\n    resp = conn.urlopen(\n  File \"/home/marius/miniconda3/envs/ccai2022/lib/python3.10/site-packages/urllib3/connectionpool.py\", line 785, in urlopen\n    retries = retries.increment(\n  File \"/home/marius/miniconda3/envs/ccai2022/lib/python3.10/site-packages/urllib3/util/retry.py\", line 592, in increment\n    raise MaxRetryError(_pool, url, error or ResponseError(cause))\nurllib3.exceptions.MaxRetryError: HTTPConnectionPool(host='127.0.0.1', port=5000): Max retries exceeded with url: /name (Caused by NewConnectionError('<urllib3.connection.HTTPConnection object at 0x7f0b18ad4400>: Failed to establish a new connection: [Errno 111] Connection refused'))\n\nDuring handling of the above exception, another exception occurred:\n\nTraceback (most recent call last):\n  File \"/home/marius/Desktop/project1-boptest-gym/testing/test_boptestGymEnv.py\", line 357, in test_variable_episode\n    env, _, _ = run_variable_episode.train_A2C_with_variable_episode(log_dir=log_dir,\n  File \"/home/marius/Desktop/project1-boptest-gym/examples/run_variable_episode.py\", line 85, in train_A2C_with_variable_episode\n    env = BoptestGymEnvVariableEpisodeLength(url                   = url,\n  File \"/home/marius/Desktop/project1-boptest-gym/boptestGymEnv.py\", line 164, in __init__\n    self.name = requests.get('{0}/name'.format(url)).json()['payload']\n  File \"/home/marius/miniconda3/envs/ccai2022/lib/python3.10/site-packages/requests/api.py\", line 75, in get\n    return request('get', url, params=params, **kwargs)\n  File \"/home/marius/miniconda3/envs/ccai2022/lib/python3.10/site-packages/requests/api.py\", line 61, in request\n    return session.request(method=method, url=url, **kwargs)\n  File \"/home/marius/miniconda3/envs/ccai2022/lib/python3.10/site-packages/requests/sessions.py\", line 529, in request\n    resp = self.send(prep, **send_kwargs)\n  File \"/home/marius/miniconda3/envs/ccai2022/lib/python3.10/site-packages/requests/sessions.py\", line 645, in send\n    r = adapter.send(request, **kwargs)\n  File \"/home/marius/miniconda3/envs/ccai2022/lib/python3.10/site-packages/requests/adapters.py\", line 519, in send\n    raise ConnectionError(e, request=request)\nrequests.exceptions.ConnectionError: HTTPConnectionPool(host='127.0.0.1', port=5000): Max retries exceeded with url: /name (Caused by NewConnectionError('<urllib3.connection.HTTPConnection object at 0x7f0b18ad4400>: Failed to establish a new connection: [Errno 111] Connection refused'))\n"}}